<?xml version="1.0" ?>
<!-- =================================================================================== -->
<!-- |    This document was autogenerated by xacro from dron_base.xacro                | -->
<!-- |    EDITING THIS FILE BY HAND IS NOT RECOMMENDED                                 | -->
<!-- =================================================================================== -->
<robot name="aerial_drone">
  <!-- *********************************************************************** -->
  <!-- *********************************************************************** -->
  <!-- *********************************************************************** -->
  <!-- Main body link -->
  <link name="dummy_link">
    <!-- Нет инерционных параметров для dummy_link -->
  </link>
  <joint name="dummy_to_base" type="fixed">
    <parent link="dummy_link"/>
    <child link="base_link"/>
    <origin rpy="0 0 0" xyz="0 0 0"/>
  </joint>
  <link name="base_link">
    <visual>
      <geometry>
        <box size="0.6 0.4 0.05"/>
      </geometry>
      <material name="base_material">
        <color rgba="0.1 0.1 0.1 1"/>
      </material>
    </visual>
    <collision>
      <geometry>
        <box size="0.6 0.4 0.05"/>
      </geometry>
    </collision>
    <inertial>
      <mass value="1.5"/>
      <inertia ixx="0.020312500000000004" ixy="0.0" ixz="0.0" iyy="0.0453125" iyz="0.0" izz="0.065"/>
    </inertial>
  </link>
  <!-- *********************************************************************** -->
  <!-- Roll joint -->
  <joint name="roll_joint" type="revolute">
    <parent link="base_link"/>
    <child link="roll_frame"/>
    <origin rpy="0 0 0" xyz="0 0 0.05"/>
    <axis xyz="1 0 0"/>
    <limit effort="1000" lower="-1.57" upper="1.57" velocity="10"/>
  </joint>
  <link name="roll_frame">
    <inertial>
      <mass value="0.01"/>
      <inertia ixx="3.333333333333333e-07" ixy="0.0" ixz="0.0" iyy="3.333333333333333e-07" iyz="0.0" izz="5.000000000000001e-07"/>
    </inertial>
  </link>
  <!-- *********************************************************************** -->
  <!-- Pitch joint -->
  <joint name="pitch_joint" type="revolute">
    <parent link="roll_frame"/>
    <child link="pitch_frame"/>
    <origin rpy="0 0 0" xyz="0 0 0"/>
    <axis xyz="0 1 0"/>
    <limit effort="1000" lower="-1.57" upper="1.57" velocity="10"/>
  </joint>
  <link name="pitch_frame">
    <inertial>
      <mass value="0.01"/>
      <inertia ixx="3.333333333333333e-07" ixy="0.0" ixz="0.0" iyy="3.333333333333333e-07" iyz="0.0" izz="5.000000000000001e-07"/>
    </inertial>
  </link>
  <!-- Joint for motor rotation -->
  <joint name="front_right_motor_joint" type="continuous">
    <origin rpy="0 0 0" xyz="0.3 0.2 0"/>
    <!-- Set origin, roll-pitch-yaw remains zero -->
    <parent link="base_link"/>
    <child link="front_right_motor_link"/>
    <axis xyz="0 0 1"/>
    <!-- Assuming rotation around z-axis -->
    <limit effort="0" velocity="0"/>
    <!-- No limit on velocity or effort -->
  </joint>
  <!-- *********************************************************************** -->
  <!-- Motor link -->
  <link name="front_right_motor_link">
    <visual>
      <origin rpy="0 0 0" xyz="0 0 0"/>
      <geometry>
        <cylinder length="0.05" radius="0.1"/>
      </geometry>
      <material name="motor_material">
        <color rgba="0.8 0.8 0.8 1"/>
      </material>
    </visual>
    <collision>
      <origin rpy="0 0 0" xyz="0 0 0"/>
      <geometry>
        <cylinder length="0.05" radius="0.1"/>
      </geometry>
    </collision>
    <inertial>
      <mass value="0.1"/>
      <inertia ixx="0.0002708333333333334" ixy="0.0" ixz="0.0" iyy="0.0002708333333333334" iyz="0.0" izz="0.0005000000000000001"/>
    </inertial>
  </link>
  <!-- Joint for motor rotation -->
  <joint name="front_left_motor_joint" type="continuous">
    <origin rpy="0 0 0" xyz="-0.3 0.2 0"/>
    <!-- Set origin, roll-pitch-yaw remains zero -->
    <parent link="base_link"/>
    <child link="front_left_motor_link"/>
    <axis xyz="0 0 1"/>
    <!-- Assuming rotation around z-axis -->
    <limit effort="0" velocity="0"/>
    <!-- No limit on velocity or effort -->
  </joint>
  <!-- *********************************************************************** -->
  <!-- Motor link -->
  <link name="front_left_motor_link">
    <visual>
      <origin rpy="0 0 0" xyz="0 0 0"/>
      <geometry>
        <cylinder length="0.05" radius="0.1"/>
      </geometry>
      <material name="motor_material">
        <color rgba="0.8 0.8 0.8 1"/>
      </material>
    </visual>
    <collision>
      <origin rpy="0 0 0" xyz="0 0 0"/>
      <geometry>
        <cylinder length="0.05" radius="0.1"/>
      </geometry>
    </collision>
    <inertial>
      <mass value="0.1"/>
      <inertia ixx="0.0002708333333333334" ixy="0.0" ixz="0.0" iyy="0.0002708333333333334" iyz="0.0" izz="0.0005000000000000001"/>
    </inertial>
  </link>
  <!-- Joint for motor rotation -->
  <joint name="rear_left_motor_joint" type="continuous">
    <origin rpy="0 0 0" xyz="-0.3 -0.2 0"/>
    <!-- Set origin, roll-pitch-yaw remains zero -->
    <parent link="base_link"/>
    <child link="rear_left_motor_link"/>
    <axis xyz="0 0 1"/>
    <!-- Assuming rotation around z-axis -->
    <limit effort="0" velocity="0"/>
    <!-- No limit on velocity or effort -->
  </joint>
  <!-- *********************************************************************** -->
  <!-- Motor link -->
  <link name="rear_left_motor_link">
    <visual>
      <origin rpy="0 0 0" xyz="0 0 0"/>
      <geometry>
        <cylinder length="0.05" radius="0.1"/>
      </geometry>
      <material name="motor_material">
        <color rgba="0.8 0.8 0.8 1"/>
      </material>
    </visual>
    <collision>
      <origin rpy="0 0 0" xyz="0 0 0"/>
      <geometry>
        <cylinder length="0.05" radius="0.1"/>
      </geometry>
    </collision>
    <inertial>
      <mass value="0.1"/>
      <inertia ixx="0.0002708333333333334" ixy="0.0" ixz="0.0" iyy="0.0002708333333333334" iyz="0.0" izz="0.0005000000000000001"/>
    </inertial>
  </link>
  <!-- Joint for motor rotation -->
  <joint name="rear_right_motor_joint" type="continuous">
    <origin rpy="0 0 0" xyz="0.3 -0.2 0"/>
    <!-- Set origin, roll-pitch-yaw remains zero -->
    <parent link="base_link"/>
    <child link="rear_right_motor_link"/>
    <axis xyz="0 0 1"/>
    <!-- Assuming rotation around z-axis -->
    <limit effort="0" velocity="0"/>
    <!-- No limit on velocity or effort -->
  </joint>
  <!-- *********************************************************************** -->
  <!-- Motor link -->
  <link name="rear_right_motor_link">
    <visual>
      <origin rpy="0 0 0" xyz="0 0 0"/>
      <geometry>
        <cylinder length="0.05" radius="0.1"/>
      </geometry>
      <material name="motor_material">
        <color rgba="0.8 0.8 0.8 1"/>
      </material>
    </visual>
    <collision>
      <origin rpy="0 0 0" xyz="0 0 0"/>
      <geometry>
        <cylinder length="0.05" radius="0.1"/>
      </geometry>
    </collision>
    <inertial>
      <mass value="0.1"/>
      <inertia ixx="0.0002708333333333334" ixy="0.0" ixz="0.0" iyy="0.0002708333333333334" iyz="0.0" izz="0.0005000000000000001"/>
    </inertial>
  </link>
  <gazebo>
    <plugin filename="libgazebo_ros_control.so" name="gazebo_ros_control">
      <robotNamespace>/</robotNamespace>
    </plugin>
  </gazebo>
  <gazebo>
    <plugin filename="libgazebo_mavlink_interface.so" name="mavlink_interface">
      <robotNamespace>/</robotNamespace>
      <port>14560</port>
      <!-- Указать порт, который используется PX4 -->
    </plugin>
  </gazebo>
</robot>
